Workbook

Sheet RESUMO
A1: Levantamento paramétrico - demandas de MP, Justiça e TCM (SEINFRA Ilhéus)
A2: PROVISORIO - aguarda aprovacao
A3: Estimativa preliminar paramétrica, não vinculante, para planejamento orçamentário. Preços SINAPI-BA 08/2026, não desonerado. Data: 13/10/2026. Levantamentos MP (pacote de 12/10) e Justiça (pacote de 13/10), sem dupla contagem.
A5: Nº | B5: Grupo-objeto | C5: Objeto | D5: Origem | E5: Levantamento | F5: Categoria | G5: Fonte das quantidades | H5: Mínimo (R$) | I5: Provável (R$) | J5: Máximo (R$) | K5: Aba
A6: 1 | B6: MPBA_001.9.102305.2021 | C6: Proteção e estabilização do prédio da Sociedade União Protetora dos Artífices e Operários (Centro) | D6: MPBA | E6: MP | F6: outro | G6: demanda-tipo (medidas do próprio documento) | H6: ='01_MPBA_001.9.102305.2021'!J62 -> 20375.387 | I6: ='01_MPBA_001.9.102305.2021'!K62 -> 31196.762 | J6: ='01_MPBA_001.9.102305.2021'!L62 -> 554590.52 | K6: 01_MPBA_001.9.102305.2021
A7: 2 | B7: MPBA_001.9.190096.2025 | C7: Conclusão de unidades escolares paralisadas (Recomendação MPBA 02/2025) | D7: MPBA | E7: MP | F7: escola/creche | G7: demanda-tipo (unidades não listadas) | H7: ='02_MPBA_001.9.190096.2025'!J55 -> 330852.01 | I7: ='02_MPBA_001.9.190096.2025'!K55 -> 781244.32 | J7: ='02_MPBA_001.9.190096.2025'!L55 -> 1609322.7 | K7: 02_MPBA_001.9.190096.2025
A8: 3 | B8: MPBA_001.9.24192.2024 | C8: Requalificação da drenagem pluvial da Av. Soares Lopes | D8: MPBA | E8: MP | F8: drenagem | G8: documento (extensão de 1.600 m) | H8: ='03_MPBA_001.9.24192.2024'!J41 -> 2199510.9 | I8: ='03_MPBA_001.9.24192.2024'!K41 -> 2756333 | J8: ='03_MPBA_001.9.24192.2024'!L41 -> 4174865.2 | K8: 03_MPBA_001.9.24192.2024
A9: 4 | B9: MPBA_001.9.250850.2021 | C9: Banheiro com chuveiro e grade na sede do Conselho Municipal de Educação | D9: MPBA | E9: MP | F9: outro | G9: demanda-tipo (banheiro-tipo) | H9: ='04_MPBA_001.9.250850.2021'!J38 -> 8137.2392 | I9: ='04_MPBA_001.9.250850.2021'!K38 -> 10266.795 | J9: ='04_MPBA_001.9.250850.2021'!L38 -> 16216.156 | K9: 04_MPBA_001.9.250850.2021
A10: 5 | B10: MPBA_001.9.379764.2023 | C10: Valetão aberto pela EMBASA em via pública (local não identificado) | D10: MPBA | E10: MP | F10: drenagem | G10: demanda-tipo (local não identificado) | H10: ='05_MPBA_001.9.379764.2023'!J39 -> 63307.487 | I10: ='05_MPBA_001.9.379764.2023'!K39 -> 118557.42 | J10: ='05_MPBA_001.9.379764.2023'!L39 -> 351155.12 | K10: 05_MPBA_001.9.379764.2023
A11: 6 | B11: MPBA_001.9.52800.2024 | C11: Quadra poliesportiva do distrito de Banco do Pedro | D11: MPBA | E11: MP | F11: quadra/esporte | G11: documento (1 quadra) + demanda-tipo | H11: ='06_MPBA_001.9.52800.2024'!J72 -> 638222.78 | I11: ='06_MPBA_001.9.52800.2024'!K72 -> 855621.59 | J11: ='06_MPBA_001.9.52800.2024'!L72 -> 1166732.3 | K11: 06_MPBA_001.9.52800.2024
A12: 7 | B12: MPBA_003.9.153337.2023 | C12: Reforma do Instituto Municipal de Ensino Eusínio Lavigne – IME (Av. Canavieiras, Centro) | D12: MPBA | E12: MP | F12: escola/creche | G12: demanda-tipo (área a confirmar) | H12: ='07_MPBA_003.9.153337.2023'!J53 -> 297660.86 | I12: ='07_MPBA_003.9.153337.2023'!K53 -> 907542.49 | J12: ='07_MPBA_003.9.153337.2023'!L53 -> 2481754 | K12: 07_MPBA_003.9.153337.2023
A13: 8 | B13: MPBA_003.9.198543.2025 | C13: Drenagem da Rua Jardim Alice (Banco da Vitória) | D13: MPBA | E13: MP | F13: drenagem | G13: demanda-tipo (escopo a confirmar) | H13: ='08_MPBA_003.9.198543.2025'!J39 -> 160465.94 | I13: ='08_MPBA_003.9.198543.2025'!K39 -> 282387.84 | J13: ='08_MPBA_003.9.198543.2025'!L39 -> 694200.07 | K13: 08_MPBA_003.9.198543.2025
A14: 9 | B14: MPBA_003.9.476383.2022 | C14: Drenagem da Rua Praia Dourada | D14: MPBA | E14: MP | F14: drenagem | G14: demanda-tipo (rua-tipo) | H14: ='09_MPBA_003.9.476383.2022'!J52 -> 307680.85 | I14: ='09_MPBA_003.9.476383.2022'!K52 -> 659546.56 | J14: ='09_MPBA_003.9.476383.2022'!L52 -> 1748983.5 | K14: 09_MPBA_003.9.476383.2022
A15: 10 | B15: MPF_1.14.001.000105-2023 | C15: Contenção de encosta da Rua Alto do Socorro (Conquista) | D15: MPF | E15: MP | F15: encosta/contenção | G15: documento (1.368,32 m², Meta 13 do Novo PAC) | H15: ='10_MPF_.000105-2023'!J33 -> 1328465.1 | I15: ='10_MPF_.000105-2023'!K33 -> 2292498.3 | J15: ='10_MPF_.000105-2023'!L33 -> 4832014.3 | K15: 10_MPF_.000105-2023
A16: 11 | B16: MPF_1.14.001.000183-2023 | C16: 96 casas e parques lineares pós-chuvas de 2021 (Salobrinho, Banco da Vitória e Vila Cachoeira) | D16: MPF | E16: MP | F16: habitação | G16: documento (96 casas e 5 parques lineares) | H16: ='11_MPF_.000183-2023'!J57 -> 7461124.6 | I16: ='11_MPF_.000183-2023'!K57 -> 8393660.7 | J16: ='11_MPF_.000183-2023'!L57 -> 10752292 | K16: 11_MPF_.000183-2023
A17: 12 | B17: SN_MPF-OBRAS_FNDE_2023 | C17: Obras FNDE: Escola Vila Lídia, Quadra do Vilela e Creche Nossa Senhora da Vitória | D17: MPF | E17: MP | F17: escola/creche | G17: demanda-tipo (situação das obras não informada) | H17: =12_SN_MPF_FNDE_2023!J138 -> 1290541.4 | I17: =12_SN_MPF_FNDE_2023!K138 -> 2284651.8 | J17: =12_SN_MPF_FNDE_2023!L138 -> 3763734.4 | K17: 12_SN_MPF_FNDE_2023
A18: 13 | B18: MPT_000120.2022.05.001.7 | C18: Condições de trabalho e reforma do prédio do SAMU de Ilhéus | D18: MPT | E18: MP | F18: outro | G18: demanda-tipo (área a confirmar) | H18: ='13_MPT_000120.2022'!J52 -> 43249.122 | I18: ='13_MPT_000120.2022'!K52 -> 139248.08 | J18: ='13_MPT_000120.2022'!L52 -> 400710.8 | K18: 13_MPT_000120.2022
A19: 14 | B19: MPT_000252.2024.05.001.5 | C19: Condições do prédio do Arquivo Público Municipal | D19: MPT | E19: MP | F19: outro | G19: demanda-tipo (área a confirmar) | H19: ='14_MPT_000252.2024'!J53 -> 62764.169 | I19: ='14_MPT_000252.2024'!K53 -> 229637.2 | J19: ='14_MPT_000252.2024'!L53 -> 797089.81 | K19: 14_MPT_000252.2024
A20: 15 | B20: MPT_000282.2023.05.001.4 | C20: Condições estruturais da Clínica Municipal de Atendimento Especializado - CMAE (Av. Canavieiras) | D20: MPT | E20: MP | F20: outro | G20: demanda-tipo (área a confirmar) | H20: ='15_MPT_000282.2023'!J52 -> 62764.169 | I20: ='15_MPT_000282.2023'!K52 -> 207030.95 | J20: ='15_MPT_000282.2023'!L52 -> 598900.3 | K20: 15_MPT_000282.2023
A21: 16 | B21: MPT_000393.2023.05.001.6 | C21: Cozinhas e áreas de limpeza das escolas municipais (saúde e segurança do trabalho) | D21: MPT | E21: MP | F21: escola/creche | G21: demanda-tipo (unidades não listadas) | H21: ='16_MPT_000393.2023'!J34 -> 41628.819 | I21: ='16_MPT_000393.2023'!K34 -> 88512.429 | J21: ='16_MPT_000393.2023'!L34 -> 208379.65 | K21: 16_MPT_000393.2023
A22: 17 | B22: JUSTICA_0006323-71.2012.8.05.0103 | C22: Requalificação do Estádio Municipal Mário Pessoa (Cidade Nova) – TAC | D22: Justiça | E22: MP | F22: quadra/esporte | G22: demanda-tipo (itens do TAC) | H22: ='17_TJBA_0006323-71.2012'!J61 -> 280956.1 | I22: ='17_TJBA_0006323-71.2012'!K61 -> 579542.15 | J22: ='17_TJBA_0006323-71.2012'!L61 -> 1434218.3 | K22: 17_TJBA_0006323-71.2012
A23: 18 | B23: JUSTICA_8003152-18.2022.8.05.0103 | C23: Drenagem pluvial e alagamentos nas Ruas Castro Alves e Barão do Rio Branco (Pontal) | D23: Justiça | E23: MP | F23: drenagem | G23: demanda-tipo (duas ruas) | H23: ='18_TJBA_8003152-18.2022'!J39 -> 315078.63 | I23: ='18_TJBA_8003152-18.2022'!K39 -> 549169.41 | J23: ='18_TJBA_8003152-18.2022'!L39 -> 1380290.2 | K23: 18_TJBA_8003152-18.2022
A24: 19 | B24: JUSTICA_8005263-04.2024.8.05.0103 | C24: Drenagem e pavimentação da Rua Aracuã (Nossa Senhora das Vitórias) | D24: Justiça | E24: MP | F24: drenagem+pavimentação | G24: demanda-tipo (rua-tipo) | H24: ='19_TJBA_8005263-04.2024'!J52 -> 307680.85 | I24: ='19_TJBA_8005263-04.2024'!K52 -> 659546.56 | J24: ='19_TJBA_8005263-04.2024'!L52 -> 1748983.5 | K24: 19_TJBA_8005263-04.2024
A25: 20 | B25: JUSTICA_8005837-61.2023.8.05.0103 | C25: Abrigos de ônibus da Rodovia Jorge Amado (BR-415), perto do IFBA | D25: Justiça | E25: MP | F25: outro | G25: demanda-tipo (abrigo-tipo) | H25: ='20_TJBA_8005837-61.2023'!J28 -> 25781.309 | I25: ='20_TJBA_8005837-61.2023'!K28 -> 41112.737 | J25: ='20_TJBA_8005837-61.2023'!L28 -> 64526.214 | K25: 20_TJBA_8005837-61.2023
A26: 21 | B26: TCM_03973e23-CRECHE_TEOTONIO_VILELA | C26: Creche Municipal Padrão de 6 salas da Rua Genésio Santos (Teotônio Vilela) | D26: TCM | E26: MP | F26: escola/creche | G26: documento (6 salas) + demanda-tipo | H26: =21_TCM_03973e23!J55 -> 385923.81 | I26: =21_TCM_03973e23!K55 -> 781244.32 | J26: =21_TCM_03973e23!L55 -> 1448377.8 | K26: 21_TCM_03973e23
A27: 22 | B27: SN_COMPLEXO_ESPORTIVO_CAMPO_DO_RODAO | C27: Requalificação e ampliação do Complexo Esportivo Campo do Rodão (Teotônio Vilela) | D27: outro | E27: MP | F27: quadra/esporte | G27: demanda-tipo (campo-tipo) | H27: =22_SN_CAMPO_DO_RODAO!J63 -> 278660.29 | I27: =22_SN_CAMPO_DO_RODAO!K63 -> 426327.92 | J27: =22_SN_CAMPO_DO_RODAO!L63 -> 651156.79 | K27: 22_SN_CAMPO_DO_RODAO
A28: 23 | B28: JUSTICA_0001568-38.2011.8.05.0103 | C28: Infraestrutura básica do Loteamento Santa Cruz (cumprimento de sentença) | D28: Justiça | E28: Justiça | F28: drenagem+pavimentação | G28: demanda-tipo (extensão de vias a confirmar) | H28: ='23_TJBA_0001568-38.2011'!J64 -> 1348883.2 | I28: ='23_TJBA_0001568-38.2011'!K64 -> 2846250.3 | J28: ='23_TJBA_0001568-38.2011'!L64 -> 7453266.7 | K28: 23_TJBA_0001568-38.2011
A29: 24 | B29: JUSTICA_8007670-17.2023.8.05.0103 | C29: Estabilização de encosta da Ladeira Júlio Bagana / Rua Rio Almada (Tapera) | D29: Justiça | E29: Justiça | F29: encosta/contenção | G29: demanda-tipo (área da encosta a confirmar) | H29: ='24_TJBA_8007670-17.2023'!J33 -> 584464.71 | I29: ='24_TJBA_8007670-17.2023'!K33 -> 1676406.2 | J29: ='24_TJBA_8007670-17.2023'!L33 -> 4943798.2 | K29: 24_TJBA_8007670-17.2023
A30: 25 | B30: JUSTICA_8008589-69.2024.8.05.0103 | C30: Unidade de Acolhimento Renascer: projeto de incêndio e reforma (Conquista) | D30: Justiça | E30: Justiça | F30: outro | G30: demanda-tipo (área a confirmar) | H30: ='25_TJBA_8008589-69.2024'!J55 -> 44832.489 | I30: ='25_TJBA_8008589-69.2024'!K55 -> 140931.38 | J30: ='25_TJBA_8008589-69.2024'!L55 -> 454217.26 | K30: 25_TJBA_8008589-69.2024
G31: TOTAL GERAL | H31: =SUM(H6:H30) -> 17889012 | I31: =SUM(I6:I30) -> 27738467 | J31: =SUM(J6:J30) -> 53729776
A33: TOTAIS MP, JUSTIÇA E GERAL (MP = pacote do MP de 12/10, inclui processos judiciais e TCM nele; Justiça = objetos novos do pacote da Justiça de 13/10)
A34: Chave | G34: Objetos | H34: Mínimo (R$) | I34: Provável (R$) | J34: Máximo (R$)
A35: MP | G35: =COUNTIF($E$6:$E$30,A35) -> 22 | H35: =SUMIF($E$6:$E$30,$A35,H$6:H$30) -> 15910832 | I35: =SUMIF($E$6:$E$30,$A35,I$6:I$30) -> 23074879 | J35: =SUMIF($E$6:$E$30,$A35,J$6:J$30) -> 40878494
A36: Justiça | G36: =COUNTIF($E$6:$E$30,A36) -> 3 | H36: =SUMIF($E$6:$E$30,$A36,H$6:H$30) -> 1978180.4 | I36: =SUMIF($E$6:$E$30,$A36,I$6:I$30) -> 4663587.9 | J36: =SUMIF($E$6:$E$30,$A36,J$6:J$30) -> 12851282
A37: GERAL (MP + Justiça, sem dupla contagem) | H37: =SUM(H35:H36) -> 17889012 | I37: =SUM(I35:I36) -> 27738467 | J37: =SUM(J35:J36) -> 53729776
A39: Objetos "orçamento paramétrico" da Justiça já calculados no MP (não somados de novo; valor da aba do MP)
B40: JUSTICA_0006323-71.2012.8.05.0103 | C40: Requalificação do Estádio Municipal Mário Pessoa (Cidade Nova) – TAC de 2012 | G40: no MP: JUSTICA_0006323-71.2012.8.05.0103 | H40: ='17_TJBA_0006323-71.2012'!J61 -> 280956.1 | I40: ='17_TJBA_0006323-71.2012'!K61 -> 579542.15 | J40: ='17_TJBA_0006323-71.2012'!L61 -> 1434218.3 | K40: 17_TJBA_0006323-71.2012
B41: JUSTICA_8005837-61.2023.8.05.0103 | C41: Abrigos de ônibus na Rodovia Jorge Amado (BR-415), perto do IFBA | G41: no MP: JUSTICA_8005837-61.2023.8.05.0103 | H41: ='20_TJBA_8005837-61.2023'!J28 -> 25781.309 | I41: ='20_TJBA_8005837-61.2023'!K28 -> 41112.737 | J41: ='20_TJBA_8005837-61.2023'!L28 -> 64526.214 | K41: 20_TJBA_8005837-61.2023
B42: TCM_03973e23 | C42: Creche Municipal Padrão de 6 salas da Rua Genésio Santos (Teotônio Vilela) | G42: no MP: TCM_03973e23-CRECHE_TEOTONIO_VILELA | H42: =21_TCM_03973e23!J55 -> 385923.81 | I42: =21_TCM_03973e23!K55 -> 781244.32 | J42: =21_TCM_03973e23!L55 -> 1448377.8 | K42: 21_TCM_03973e23
A44: Total por origem
...

Sheet PARAMETROS
A1: Parâmetros da estimativa (BDI, contingência e fator regional)
A2: PROVISORIO - aguarda aprovacao
A3: Custo = Σ(Quantidade × Preço unitário) × (1 + BDI) × (1 + Contingência) × Fator regional. Células amarelas: valores a aprovar.
A5: Parâmetro | B5: Mínimo | C5: Provável | D5: Máximo | E5: Fonte / justificativa
A6: BDI - edificações, encostas, quadras e outros | B6: 0.2034 | C6: 0.2212 | D6: 0.25 | E6: Acórdão n. 2.622/2013-TCU-Plenário, "construção de edifícios": 1º quartil / médio / 3º quartil (sem CPRB; regime não desonerado).
A7: BDI - pavimentação e drenagem de vias | B7: 0.196 | C7: 0.2097 | D7: 0.2423 | E7: Acórdão n. 2.622/2013-TCU-Plenário, "construção de rodovias e ferrovias": 1º quartil / médio / 3º quartil (sem CPRB).
A8: Contingência (projeto, sondagem, topografia, licenciamento, fiscalização) | B8: 0.05 | C8: 0.1 | D8: 0.15 | E8: Parâmetro técnico declarado; teto de referência: precisão de ±30% para estudos preliminares (OT-IBR 004/2012, IBRAOP).
A9: Fator regional | B9: 1 | C9: 1 | D9: 1.1 | E9: SINAPI coleta preços na capital (Salvador). Máximo cobre frete até Ilhéus, acesso difícil e mobilização (parâmetro declarado).
A11: Preços unitários: SINAPI/CAIXA, ref. 08/2026, Bahia (localidade Salvador), regime não desonerado; encargos sociais horista 117,73% e mensalista 72,85%.
A12: Ver proposta_bdi_contingencia_fator.md para as fontes conferidas e as limitações da conferência.

Sheet 01_MPBA_001.9.102305.2021
A1: 01 - Proteção e estabilização do prédio da Sociedade União Protetora dos Artífices e Operários (Centro)
A2: PROVISORIO - aguarda aprovacao
A4: Grupo-objeto | B4: MPBA_001.9.102305.2021
A5: Levantamento | B5: MP
A6: Origem | B6: MPBA
A7: Categoria | B7: outro
A8: Local | B8: Praça José Marcelino, s/n, Centro
A9: Fonte das quantidades | B9: demanda-tipo (medidas do próprio documento)
A10: Preços | B10: SINAPI/CAIXA ref. 08/2026, BA, não desonerado (código de cada item na coluna B)
A11: BDI aplicado | B11: edificações (Acórdão 2.622/2013, construção de edifícios)
A12: Premissas | B12: Medidas citadas no documento: tapumes, escoramento da fachada com estroncas de eucalipto, rede de proteção e lona na cobertura.
B13: Fachada 150/250/400 m², cobertura 250/350/500 m², 30/40/60 estroncas (premissa; medir no local).
B14: Cenário máximo inclui início da estabilização/recuperação (reforma pesada de 500 m²). Restauro de prédio histórico não está incluído.
B15: Locação do andaime e da tela não têm preço no SINAPI-BA usado; só montagem e colocação.
A17: Macroetapa | B17: Código SINAPI | C17: Tipo | D17: Descrição | E17: Unid. | F17: Preço unit. (R$) | G17: Qtd. mínimo | H17: Qtd. provável | I17: Qtd. máximo | J17: Total mínimo (R$) | K17: Total provável (R$) | L17: Total máximo (R$) | M17: Memória de cálculo
A18: 1. Isolamento | B18: 98458 | C18: SINAPI composição | D18: TAPUME COM COMPENSADO DE MADEIRA. AF_03/2024 | E18: M2 | F18: 105.08 | G18: 50 | H18: 66 | I18: 90 | J18: =F18*G18 -> 5254 | K18: =F18*H18 -> 6935.28 | L18: =F18*I18 -> 9457.2 | M18: tapume de compensado no perímetro frontal
A19: 2. Escoramento da fachada | B19: 14439 | C19: SINAPI insumo | D19: PONTALETE ROLICO SEM TRATAMENTO, D = 8 A 11 CM, H = 6 M, EM EUCALIPTO OU EQUIVALENTE DA REGIAO - BRUTA (PARA ESCORAMENTO) | E19: M | F19: 5.57 | G19: 180 | H19: 240 | I19: 360 | J19: =F19*G19 -> 1002.6 | K19: =F19*H19 -> 1336.8 | L19: =F19*I19 -> 2005.2 | M19: estroncas de eucalipto 6 m
A20: 2. Escoramento da fachada | B20: 88262 | C20: SINAPI composição | D20: CARPINTEIRO DE FORMAS COM ENCARGOS COMPLEMENTARES | E20: H | F20: 35.15 | G20: 60 | H20: 80 | I20: 120 | J20: =F20*G20 -> 2109 | K20: =F20*H20 -> 2812 | L20: =F20*I20 -> 4218 | M20: carpinteiro, 2 h por estronca
A21: 2. Escoramento da fachada | B21: 88316 | C21: SINAPI composição | D21: SERVENTE COM ENCARGOS COMPLEMENTARES | E21: H | F21: 26.14 | G21: 60 | H21: 80 | I21: 120 | J21: =F21*G21 -> 1568.4 | K21: =F21*H21 -> 2091.2 | L21: =F21*I21 -> 3136.8 | M21: servente, 2 h por estronca
A22: 3. Proteção da fachada | B22: 97063 | C22: SINAPI composição | D22: MONTAGEM E DESMONTAGEM DE ANDAIME MODULAR FACHADEIRO, COM PISO METÁLICO, PARA EDIFÍCIOS COM MULTIPLOS PAVIMENTOS (EXCLUSIVE ANDAIME E LIMPEZA). AF_03/2024 | E22: M2 | F22: 27.41 | G22: 150 | H22: 250 | I22: 400 | J22: =F22*G22 -> 4111.5 | K22: =F22*H22 -> 6852.5 | L22: =F22*I22 -> 10964 | M22: montagem/desmontagem de andaime fachadeiro (exclusive locação)
A23: 3. Proteção da fachada | B23: 97062 | C23: SINAPI composição | D23: COLOCAÇÃO DE TELA EM ANDAIME FACHADEIRO. AF_03/2024 | E23: M2 | F23: 7.11 | G23: 150 | H23: 250 | I23: 400 | J23: =F23*G23 -> 1066.5 | K23: =F23*H23 -> 1777.5 | L23: =F23*I23 -> 2844 | M23: colocação de tela de proteção na fachada
A24: 4. Proteção da cobertura | B24: 42408 | C24: SINAPI insumo | D24: LONA PLASTICA EXTRA FORTE PRETA, E = 200 MICRA | E24: M2 | F24: 2.1 | G24: 275 | H24: 385 | I24: 550 | J24: =F24*G24 -> 577.5 | K24: =F24*H24 -> 808.5 | L24: =F24*I24 -> 1155 | M24: lona plástica 200 micra (+10% de transpasse)
A25: 4. Proteção da cobertura | B25: 88316 | C25: SINAPI composição | D25: SERVENTE COM ENCARGOS COMPLEMENTARES | E25: H | F25: 26.14 | G25: 16.67 | H25: 23.33 | I25: 33.33 | J25: =F25*G25 -> 435.7538 | K25: =F25*H25 -> 609.8462 | L25: =F25*I25 -> 871.2462 | M25: servente para colocar a lona
A26: Início da estabilização/recuperação - 1. Serviços preliminares | B26: 103689 | C26: SINAPI composição | D26: FORNECIMENTO E INSTALAÇÃO DE PLACA DE OBRA COM CHAPA GALVANIZADA E ESTRUTURA DE MADEIRA. AF_03/2022_PS | E26: M2 | F26: 454.97 | G26: 0 | H26: 0 | I26: 6 | J26: =F26*G26 -> 0 | K26: =F26*H26 -> 0 | L26: =F26*I26 -> 2729.82 | M26: placa de obra
A27: Início da estabilização/recuperação - 2. Demolições e retiradas | B27: 97647 | C27: SINAPI composição | D27: REMOÇÃO DE TELHAS DE FIBROCIMENTO METÁLICA E CERÂMICA, DE FORMA MANUAL, SEM REAPROVEITAMENTO. AF_09/2023 | E27: M2 | F27: 4.43 | G27: 0 | H27: 0 | I27: 625 | J27: =F27*G27 -> 0 | K27: =F27*H27 -> 0 | L27: =F27*I27 -> 2768.75 | M27: remoção de telhas
A28: Início da estabilização/recuperação - 2. Demolições e retiradas | B28: 97650 | C28: SINAPI composição | D28: REMOÇÃO DE TRAMA DE MADEIRA PARA COBERTURA, DE FORMA MANUAL, SEM REAPROVEITAMENTO. AF_09/2023 | E28: M2 | F28: 9.56 | G28: 0 | H28: 0 | I28: 312.5 | J28: =F28*G28 -> 0 | K28: =F28*H28 -> 0 | L28: =F28*I28 -> 2987.5 | M28: remoção de trama de madeira (metade da área refeita)
A29: Início da estabilização/recuperação - 2. Demolições e retiradas | B29: 97640 | C29: SINAPI composição | D29: REMOÇÃO DE FORROS DE DRYWALL, PVC E FIBROMINERAL, DE FORMA MANUAL, SEM REAPROVEITAMENTO. AF_09/2023 | E29: M2 | F29: 2.58 | G29: 0 | H29: 0 | I29: 500 | J29: =F29*G29 -> 0 | K29: =F29*H29 -> 0 | L29: =F29*I29 -> 1290 | M29: remoção de forro
... A57: Início da estabilização/recuperação - 9. Entulho | B57: 95875 | C57: SINAPI composição | D57: TRANSPORTE COM CAMINHÃO BASCULANTE DE 10 M³, EM VIA URBANA PAVIMENTADA, DMT ATÉ 30 KM (UNIDADE: M3XKM). AF_02/2026 | E57: M3XKM | F57: 2.83 | G57: 0 | H57: 0 | I57: 250 | J57: =F57*G57 -> 0 | K57: =F57*H57 -> 0 | L57: =F57*I57 -> 707.5 | M57: transporte de entulho, DMT 10 km
I58: Custo direto | J58: =SUM(J18:J57) -> 16125.254 | K58: =SUM(K18:K57) -> 23223.626 | L58: =SUM(L18:L57) -> 350729.18
I59: BDI | J59: =PARAMETROS!$B$6 -> 0.2034 | K59: =PARAMETROS!$C$6 -> 0.2212 | L59: =PARAMETROS!$D$6 -> 0.25
I60: Contingência | J60: =PARAMETROS!$B$8 -> 0.05 | K60: =PARAMETROS!$C$8 -> 0.1 | L60: =PARAMETROS!$D$8 -> 0.15
I61: Fator regional | J61: =PARAMETROS!$B$9 -> 1 | K61: =PARAMETROS!$C$9 -> 1 | L61: =PARAMETROS!$D$9 -> 1.1
I62: TOTAL ESTIMADO (R$) | J62: =J58*(1+J59)*(1+J60)*J61 -> 20375.387 | K62: =K58*(1+K59)*(1+K60)*K61 -> 31196.762 | L62: =L58*(1+L59)*(1+L60)*L61 -> 554590.52
A64: Estimativa preliminar paramétrica, não vinculante, para planejamento orçamentário. Não substitui o orçamento detalhado do projeto. PROVISORIO - aguarda aprovacao

Sheet 02_MPBA_001.9.190096.2025
A1: 02 - Conclusão de unidades escolares paralisadas (Recomendação MPBA 02/2025)
A2: PROVISORIO - aguarda aprovacao
A4: Grupo-objeto | B4: MPBA_001.9.190096.2025
A5: Levantamento | B5: MP
A6: Origem | B6: MPBA
A7: Categoria | B7: escola/creche
A8: Local | B8: Rede municipal de ensino de Ilhéus (cita a Escola Municipal Vovó Isaac, Rua do Cano)
A9: Fonte das quantidades | B9: demanda-tipo (unidades não listadas)
A10: Preços | B10: SINAPI/CAIXA ref. 08/2026, BA, não desonerado (código de cada item na coluna B)
A11: BDI aplicado | B11: edificações (Acórdão 2.622/2013, construção de edifícios)
A12: Premissas | B12: A Recomendação não lista as escolas; foi estimada só a conclusão da Escola Municipal Vovó Isaac (citada).
B13: Escola de 600/800/1.000 m² com remanescente de 30/50/70% (área equivalente 180/400/700 m²).
B14: Edificação térrea-tipo por m²: concreto 0,12 m³/m², aço 10 kg/m², fôrma 1,1 m²/m², alvenaria 1,5 m²/m², cobertura em telha cerâmica (1,25 m²/m²), forro de PVC, piso cerâmico, 1 porta a cada 15 m², janelas 0,15 m²/m², instalações simplificadas.
A16: Macroetapa | B16: Código SINAPI | C16: Tipo | D16: Descrição | E16: Unid. | F16: Preço unit. (R$) | G16: Qtd. mínimo | H16: Qtd. provável | I16: Qtd. máximo | J16: Total mínimo (R$) | K16: Total provável (R$) | L16: Total máximo (R$) | M16: Memória de cálculo
A17: 1. Serviços preliminares | B17: 99059 | C17: SINAPI composição | D17: LOCAÇÃO CONVENCIONAL DE OBRA, UTILIZANDO GABARITO DE TÁBUAS CORRIDAS PONTALETADAS A CADA 2,00M - 2 UTILIZAÇÕES. AF_03/2024 | E17: M | F17: 75.94 | G17: 45 | H17: 100 | I17: 175 | J17: =F17*G17 -> 3417.3 | K17: =F17*H17 -> 7594 | L17: =F17*I17 -> 13289.5 | M17: locação de obra, 0,25 m de gabarito por m²
A18: 2. Fundação e estrutura | B18: 93358 | C18: SINAPI composição | D18: ESCAVAÇÃO MANUAL DE VALA. AF_09/2024 | E18: M3 | F18: 103.4 | G18: 14.4 | H18: 32 | I18: 56 | J18: =F18*G18 -> 1488.96 | K18: =F18*H18 -> 3308.8 | L18: =F18*I18 -> 5790.4 | M18: escavação manual, 0,08 m³/m²
A19: 2. Fundação e estrutura | B19: 103672 | C19: SINAPI composição | D19: CONCRETAGEM DE PILARES, FCK = 25 MPA, COM USO DE BOMBA - LANÇAMENTO, ADENSAMENTO E ACABAMENTO. AF_02/2022_PS | E19: M3 | F19: 828.32 | G19: 21.6 | H19: 48 | I19: 84 | J19: =F19*G19 -> 17891.712 | K19: =F19*H19 -> 39759.36 | L19: =F19*I19 -> 69578.88 | M19: concreto estrutural fck 25 MPa, 0,12 m³/m²
A20: 2. Fundação e estrutura | B20: 92762 | C20: SINAPI composição | D20: ARMAÇÃO DE PILAR OU VIGA DE ESTRUTURA CONVENCIONAL DE CONCRETO ARMADO UTILIZANDO AÇO CA-50 DE 10,0 MM - MONTAGEM. AF_06/2022 | E20: KG | F20: 10.41 | G20: 1800 | H20: 4000 | I20: 7000 | J20: =F20*G20 -> 18738 | K20: =F20*H20 -> 41640 | L20: =F20*I20 -> 72870 | M20: armação CA-50, 10 kg/m²
A21: 2. Fundação e estrutura | B21: 92421 | C21: SINAPI composição | D21: MONTAGEM E DESMONTAGEM DE FÔRMA DE PILARES RETANGULARES E ESTRUTURAS SIMILARES, PÉ-DIREITO DUPLO, EM CHAPA DE MADEIRA COMPENSADA RESINADA, 4 UTILIZAÇÕES. AF_09/2020 | E21: M2 | F21: 122.64 | G21: 198 | H21: 440 | I21: 770 | J21: =F21*G21 -> 24282.72 | K21: =F21*H21 -> 53961.6 | L21: =F21*I21 -> 94432.8 | M21: fôrmas, 1,1 m²/m²
A22: 3. Vedação e revestimentos | B22: 103328 | C22: SINAPI composição | D22: ALVENARIA DE VEDAÇÃO DE BLOCOS CERÂMICOS FURADOS NA HORIZONTAL DE 9X19X19 CM (ESPESSURA 9 CM) E ARGAMASSA DE ASSENTAMENTO COM PREPARO EM BETONEIRA. AF_08/2026 | E22: M2 | F22: 119.54 | G22: 270 | H22: 600 | I22: 1050 | J22: =F22*G22 -> 32275.8 | K22: =F22*H22 -> 71724 | L22: =F22*I22 -> 125517 | M22: alvenaria de vedação, 1,5 m²/m²
A23: 3. Vedação e revestimentos | B23: 87879 | C23: SINAPI composição | D23: CHAPISCO APLICADO EM ALVENARIAS E ESTRUTURAS DE CONCRETO INTERNAS, COM COLHER DE PEDREIRO. ARGAMASSA TRAÇO 1:3 COM PREPARO EM BETONEIRA 400L. AF_10/2022 | E23: M2 | F23: 6.03 | G23: 540 | H23: 1200 | I23: 2100 | J23: =F23*G23 -> 3256.2 | K23: =F23*H23 -> 7236 | L23: =F23*I23 -> 12663 | M23: chapisco nas duas faces
A24: 3. Vedação e revestimentos | B24: 104958 | C24: SINAPI composição | D24: MASSA ÚNICA, EM ARGAMASSA TRAÇO 1:2:8 PREPARO MECÂNICO, APLICADA MANUALMENTE EM PAREDES INTERNAS DE AMBIENTES COM ÁREA MAIOR QUE 10M², E = 10MM, COM TALISCAS. AF_03/2024 | E24: M2 | F24: 31.79 | G24: 432 | H24: 960 | I24: 1680 | J24: =F24*G24 -> 13733.28 | K24: =F24*H24 -> 30518.4 | L24: =F24*I24 -> 53407.2 | M24: massa única interna
A25: 3. Vedação e revestimentos | B25: 104235 | C25: SINAPI composição | D25: EMBOÇO OU MASSA ÚNICA EM ARGAMASSA INDUSTRIALIZADA, PREPARO MECÂNICA E APLICAÇÃO COM EQUIPAMENTO DE MISTURA E PROJEÇÃO DE 1,5 M3/H DE ARGAMASSA EM PANOS DE FACHADA SEM PRESENÇA DE VÃOS, ESPESSURA DE 25 MM, ACESSO POR ANDAIME. AF_08/2022 | E25: M2 | F25: 83.28 | G25: 108 | H25: 240 | I25: 420 | J25: =F25*G25 -> 8994.24 | K25: =F25*H25 -> 19987.2 | L25: =F25*I25 -> 34977.6 | M25: emboço externo
A26: 3. Vedação e revestimentos | B26: 87265 | C26: SINAPI composição | D26: REVESTIMENTO CERÂMICO PARA PAREDES INTERNAS COM PLACAS TIPO ESMALTADA DE DIMENSÕES 20X20 CM APLICADAS NA ALTURA INTEIRA DAS PAREDES. AF_02/2023_PE | E26: M2 | F26: 59.3 | G26: 54 | H26: 120 | I26: 210 | J26: =F26*G26 -> 3202.2 | K26: =F26*H26 -> 7116 | L26: =F26*I26 -> 12453 | M26: revestimento cerâmico em áreas molhadas
A27: 4. Pisos | B27: 95241 | C27: SINAPI composição | D27: LASTRO DE CONCRETO MAGRO, APLICADO EM PISOS, LAJES SOBRE SOLO OU RADIERS, ESPESSURA DE 5 CM. AF_01/2024 | E27: M2 | F27: 48.41 | G27: 180 | H27: 400 | I27: 700 | J27: =F27*G27 -> 8713.8 | K27: =F27*H27 -> 19364 | L27: =F27*I27 -> 33887 | M27: lastro de concreto magro 5 cm
A28: 4. Pisos | B28: 98680 | C28: SINAPI composição | D28: PISO CIMENTADO, TRAÇO 1:5 (CIMENTO E AREIA), ACABAMENTO LISO, ESPESSURA 3,0 CM, PREPARO MECÂNICO DA ARGAMASSA. AF_02/2026 | E28: M2 | F28: 58.19 | G28: 180 | H28: 400 | I28: 700 | J28: =F28*G28 -> 10474.2 | K28: =F28*H28 -> 23276 | L28: =F28*I28 -> 40733 | M28: regularização/contrapiso cimentado 3 cm
... A50: 10. Prevenção contra incêndio | B50: 37556 | C50: SINAPI insumo | D50: PLACA DE SINALIZACAO DE SEGURANCA CONTRA INCENDIO, FOTOLUMINESCENTE, QUADRADA, *20 X 20* CM, EM PVC *2* MM ANTI-CHAMAS (SIMBOLOS, CORES E PICTOGRAMAS CONFORME NBR 16820) | E50: UN | F50: 20.47 | G50: 3.6 | H50: 8 | I50: 14 | J50: =F50*G50 -> 73.692 | K50: =F50*H50 -> 163.76 | L50: =F50*I50 -> 286.58 | M50: placa fotoluminescente de rota de fuga
I51: Custo direto | J51: =SUM(J17:J50) -> 261839.08 | K51: =SUM(K17:K50) -> 581577.22 | L51: =SUM(L17:L50) -> 1017753.5
I52: BDI | J52: =PARAMETROS!$B$6 -> 0.2034 | K52: =PARAMETROS!$C$6 -> 0.2212 | L52: =PARAMETROS!$D$6 -> 0.25
I53: Contingência | J53: =PARAMETROS!$B$8 -> 0.05 | K53: =PARAMETROS!$C$8 -> 0.1 | L53: =PARAMETROS!$D$8 -> 0.15
I54: Fator regional | J54: =PARAMETROS!$B$9 -> 1 | K54: =PARAMETROS!$C$9 -> 1 | L54: =PARAMETROS!$D$9 -> 1.1
I55: TOTAL ESTIMADO (R$) | J55: =J51*(1+J52)*(1+J53)*J54 -> 330852.01 | K55: =K51*(1+K52)*(1+K53)*K54 -> 781244.32 | L55: =L51*(1+L52)*(1+L53)*L54 -> 1609322.7
A57: Estimativa preliminar paramétrica, não vinculante, para planejamento orçamentário. Não substitui o orçamento detalhado do projeto. PROVISORIO - aguarda aprovacao

Sheet 03_MPBA_001.9.24192.2024
A1: 03 - Requalificação da drenagem pluvial da Av. Soares Lopes
A2: PROVISORIO - aguarda aprovacao
A4: Grupo-objeto | B4: MPBA_001.9.24192.2024
A5: Levantamento | B5: MP
A6: Origem | B6: MPBA
A7: Categoria | B7: drenagem
A8: Local | B8: Av. Soares Lopes
A9: Fonte das quantidades | B9: documento (extensão de 1.600 m)
A10: Preços | B10: SINAPI/CAIXA ref. 08/2026, BA, não desonerado (código de cada item na coluna B)
A11: BDI aplicado | B11: vias e drenagem (Acórdão 2.622/2013, rodovias e ferrovias)
A12: Premissas | B12: Extensão de 1.600 m citada no pedido de prorrogação da SEINFRA (minuta de 12/11/2024).
B13: Rede principal DN 800/1.000/1.200 mm (premissa até haver projeto).
B14: Microdrenagem em via existente: vala com largura DN + 0,6 m e profundidade DN + 1,0 m, PV a cada 40 m, 2 bocas de lobo a cada 40 m, recomposição de base (20 cm) e CBUQ (5 cm) na faixa da vala, bota-fora a 10 km.
A16: Macroetapa | B16: Código SINAPI | C16: Tipo | D16: Descrição | E16: Unid. | F16: Preço unit. (R$) | G16: Qtd. mínimo | H16: Qtd. provável | I16: Qtd. máximo | J16: Total mínimo (R$) | K16: Total provável (R$) | L16: Total máximo (R$) | M16: Memória de cálculo
A17: 1. Serviços preliminares | B17: 103689 | C17: SINAPI composição | D17: FORNECIMENTO E INSTALAÇÃO DE PLACA DE OBRA COM CHAPA GALVANIZADA E ESTRUTURA DE MADEIRA. AF_03/2022_PS | E17: M2 | F17: 454.97 | G17: 6 | H17: 6 | I17: 6 | J17: =F17*G17 -> 2729.82 | K17: =F17*H17 -> 2729.82 | L17: =F17*I17 -> 2729.82 | M17: placa de obra 3 m x 2 m
A18: 2. Drenagem | B18: 90082 | C18: SINAPI composição | D18: ESCAVAÇÃO MECANIZADA DE VALA COM PROF. ATÉ 1,5 M (MÉDIA MONTANTE E JUSANTE/UMA COMPOSIÇÃO POR TRECHO), ESCAVADEIRA (0,8 M3), LARG. DE 1,5 M A 2,5 M, EM SOLO DE 1A CATEGORIA, EM LOCAIS COM ALTO NÍVEL DE INTERFERÊNCIA. AF_09/2024 | E18: M3 | F18: 10.58 | G18: 4032 | H18: 0 | I18: 0 | J18: =F18*G18 -> 42658.56 | K18: =F18*H18 -> 0 | L18: =F18*I18 -> 0 | M18: vala 1.40 m x 1.80 m x L 1600 m
A19: 2. Drenagem | B19: 92214 | C19: SINAPI composição | D19: TUBO DE CONCRETO PARA REDES COLETORAS DE ÁGUAS PLUVIAIS, DIÂMETRO DE 800 MM, JUNTA RÍGIDA, INSTALADO EM LOCAL COM BAIXO NÍVEL DE INTERFERÊNCIAS - FORNECIMENTO E ASSENTAMENTO. AF_03/2024 | E19: M | F19: 567.96 | G19: 1600 | H19: 0 | I19: 0 | J19: =F19*G19 -> 908736 | K19: =F19*H19 -> 0 | L19: =F19*I19 -> 0 | M19: rede DN 800 mm ao longo de L
A20: 2. Drenagem | B20: 93369 | C20: SINAPI composição | D20: REATERRO MECANIZADO DE VALA COM ESCAVADEIRA HIDRÁULICA (CAPACIDADE DA CAÇAMBA: 0,8 M³/POTÊNCIA: 111 HP), LARGURA 1,5 A 2,5 M, PROFUNDIDADE 1,5 A 3,0 M, COM SOLO (SEM SUBSTITUIÇÃO) DE 1ª CATEGORIA, COM COMPACTADOR DE SOLOS DE PERCUSSÃO. AF_08/2023 | E20: M3 | F20: 20.26 | G20: 3014.12 | H20: 3599.47 | I20: 4212.28 | J20: =F20*G20 -> 61066.071 | K20: =F20*H20 -> 72925.262 | L20: =F20*I20 -> 85340.793 | M20: volume da vala - volume externo do tubo
A21: 2. Drenagem | B21: 102457 | C21: SINAPI composição | D21: BASE PARA POÇO DE VISITA CIRCULAR PARA DRENAGEM, EM CONCRETO PRÉ-MOLDADO, DIÂMETRO INTERNO = 1,20 M, PROFUNDIDADE = 1,60 M, EXCLUINDO TAMPÃO. AF_05/2021 | E21: UN | F21: 2008.56 | G21: 41 | H21: 0 | I21: 0 | J21: =F21*G21 -> 82350.96 | K21: =F21*H21 -> 0 | L21: =F21*I21 -> 0 | M21: PV a cada 40 m + 1
A22: 2. Drenagem | B22: 99240 | C22: SINAPI composição | D22: ACRÉSCIMO PARA POÇO DE VISITA CIRCULAR PARA DRENAGEM, EM CONCRETO PRÉ-MOLDADO, DIÂMETRO INTERNO = 1,2 M. AF_12/2020 | E22: M | F22: 844.48 | G22: 20.5 | H22: 0 | I22: 0 | J22: =F22*G22 -> 17311.84 | K22: =F22*H22 -> 0 | L22: =F22*I22 -> 0 | M22: acréscimo médio de 0,5 m de profundidade por PV
A23: 2. Drenagem | B23: 97956 | C23: SINAPI composição | D23: CAIXA PARA BOCA DE LOBO SIMPLES RETANGULAR, EM ALVENARIA COM BLOCOS DE CONCRETO, DIMENSÕES INTERNAS: 0,6X1X1,2 M. AF_12/2020 | E23: UN | F23: 1812.94 | G23: 80 | H23: 80 | I23: 80 | J23: =F23*G23 -> 145035.2 | K23: =F23*H23 -> 145035.2 | L23: =F23*I23 -> 145035.2 | M23: boca de lobo simples, 2 a cada 40 m
A24: 2. Drenagem | B24: 92210 | C24: SINAPI composição | D24: TUBO DE CONCRETO PARA REDES COLETORAS DE ÁGUAS PLUVIAIS, DIÂMETRO DE 400 MM, JUNTA RÍGIDA, INSTALADO EM LOCAL COM BAIXO NÍVEL DE INTERFERÊNCIAS - FORNECIMENTO E ASSENTAMENTO. AF_03/2024 | E24: M | F24: 188.74 | G24: 320 | H24: 320 | I24: 320 | J24: =F24*G24 -> 60396.8 | K24: =F24*H24 -> 60396.8 | L24: =F24*I24 -> 60396.8 | M24: ligação BL-PV em DN 400 mm, 4 m por boca de lobo
A25: 2. Drenagem | B25: 100982 | C25: SINAPI composição | D25: CARGA, MANOBRA E DESCARGA DE ENTULHO EM CAMINHÃO BASCULANTE 10 M³ - CARGA COM ESCAVADEIRA HIDRÁULICA (CAÇAMBA DE 0,80 M³ / 111 HP) E DESCARGA LIVRE (UNIDADE: M3). AF_02/2026 | E25: M3 | F25: 9.88 | G25: 1017.88 | H25: 1520.53 | I25: 2123.72 | J25: =F25*G25 -> 10056.654 | K25: =F25*H25 -> 15022.836 | L25: =F25*I25 -> 20982.354 | M25: carga do solo excedente (volume do tubo)
A26: 2. Drenagem | B26: 95875 | C26: SINAPI composição | D26: TRANSPORTE COM CAMINHÃO BASCULANTE DE 10 M³, EM VIA URBANA PAVIMENTADA, DMT ATÉ 30 KM (UNIDADE: M3XKM). AF_02/2026 | E26: M3XKM | F26: 2.83 | G26: 10178.76 | H26: 15205.31 | I26: 21237.17 | J26: =F26*G26 -> 28805.891 | K26: =F26*H26 -> 43031.027 | L26: =F26*I26 -> 60101.191 | M26: transporte do excedente, DMT 10 km
A27: 3. Recomposição do pavimento | B27: 101849 | C27: SINAPI composição | D27: RECOMPOSIÇÃO DE BASE E OU SUB-BASE PARA FECHAMENTO DE VALAS DE BRITA GRADUADA SIMPLES - INCLUSO RETIRADA E COLOCAÇÃO DO MATERIAL. AF_12/2020 | E27: M3 | F27: 232.27 | G27: 512 | H27: 0 | I27: 0 | J27: =F27*G27 -> 118922.24 | K27: =F27*H27 -> 0 | L27: =F27*I27 -> 0 | M27: base de brita graduada 20 cm na faixa da vala (1.60 m)
A28: 3. Recomposição do pavimento | B28: 102098 | C28: SINAPI composição | D28: RECOMPOSIÇÃO DE REVESTIMENTO EM CONCRETO ASFÁLTICO (AQUISIÇÃO EM USINA), PARA O FECHAMENTO DE VALAS - INCLUSO DEMOLIÇÃO DO PAVIMENTO. AF_12/2020 | E28: M3 | F28: 2136.03 | G28: 128 | H28: 144 | I28: 160 | J28: =F28*G28 -> 273411.84 | K28: =F28*H28 -> 307588.32 | L28: =F28*I28 -> 341764.8 | M28: revestimento em CBUQ 5 cm na faixa da vala (inclui demolição)
... A36: 3. Recomposição do pavimento | B36: 101849 | C36: SINAPI composição | D36: RECOMPOSIÇÃO DE BASE E OU SUB-BASE PARA FECHAMENTO DE VALAS DE BRITA GRADUADA SIMPLES - INCLUSO RETIRADA E COLOCAÇÃO DO MATERIAL. AF_12/2020 | E36: M3 | F36: 232.27 | G36: 0 | H36: 0 | I36: 640 | J36: =F36*G36 -> 0 | K36: =F36*H36 -> 0 | L36: =F36*I36 -> 148652.8 | M36: base de brita graduada 20 cm na faixa da vala (2.00 m)
I37: Custo direto | J37: =SUM(J17:J36) -> 1751481.9 | K37: =SUM(K17:K36) -> 2071387.3 | L37: =SUM(L17:L36) -> 2656595.6
I38: BDI | J38: =PARAMETROS!$B$7 -> 0.196 | K38: =PARAMETROS!$C$7 -> 0.2097 | L38: =PARAMETROS!$D$7 -> 0.2423
I39: Contingência | J39: =PARAMETROS!$B$8 -> 0.05 | K39: =PARAMETROS!$C$8 -> 0.1 | L39: =PARAMETROS!$D$8 -> 0.15
I40: Fator regional | J40: =PARAMETROS!$B$9 -> 1 | K40: =PARAMETROS!$C$9 -> 1 | L40: =PARAMETROS!$D$9 -> 1.1
I41: TOTAL ESTIMADO (R$) | J41: =J37*(1+J38)*(1+J39)*J40 -> 2199510.9 | K41: =K37*(1+K38)*(1+K39)*K40 -> 2756333 | L41: =L37*(1+L38)*(1+L39)*L40 -> 4174865.2
A43: Estimativa preliminar paramétrica, não vinculante, para planejamento orçamentário. Não substitui o orçamento detalhado do projeto. PROVISORIO - aguarda aprovacao

Sheet 04_MPBA_001.9.250850.2021
A1: 04 - Banheiro com chuveiro e grade na sede do Conselho Municipal de Educação
A2: PROVISORIO - aguarda aprovacao
A4: Grupo-objeto | B4: MPBA_001.9.250850.2021
A5: Levantamento | B5: MP
A6: Origem | B6: MPBA
A7: Categoria | B7: outro
A8: Local | B8: Sede do Conselho Municipal de Educação
A9: Fonte das quantidades | B9: demanda-tipo (banheiro-tipo)
A10: Preços | B10: SINAPI/CAIXA ref. 08/2026, BA, não desonerado (código de cada item na coluna B)
A11: BDI aplicado | B11: edificações (Acórdão 2.622/2013, construção de edifícios)
A12: Premissas | B12: Banheiro com chuveiro de cerca de 4 m² e grade de 1,0 x 2,1 m na porta de entrada, como pedido pela 6ª PJ.
B13: Quantidades de alvenaria e revestimento x 0,7 / 1,0 / 1,4; no máximo, inclui cobertura própria.
A15: Macroetapa | B15: Código SINAPI | C15: Tipo | D15: Descrição | E15: Unid. | F15: Preço unit. (R$) | G15: Qtd. mínimo | H15: Qtd. provável | I15: Qtd. máximo | J15: Total mínimo (R$) | K15: Total provável (R$) | L15: Total máximo (R$) | M15: Memória de cálculo
A16: 1. Banheiro com chuveiro | B16: 103328 | C16: SINAPI composição | D16: ALVENARIA DE VEDAÇÃO DE BLOCOS CERÂMICOS FURADOS NA HORIZONTAL DE 9X19X19 CM (ESPESSURA 9 CM) E ARGAMASSA DE ASSENTAMENTO COM PREPARO EM BETONEIRA. AF_08/2026 | E16: M2 | F16: 119.54 | G16: 7 | H16: 10 | I16: 14 | J16: =F16*G16 -> 836.78 | K16: =F16*H16 -> 1195.4 | L16: =F16*I16 -> 1673.56 | M16: alvenaria
A17: 1. Banheiro com chuveiro | B17: 87879 | C17: SINAPI composição | D17: CHAPISCO APLICADO EM ALVENARIAS E ESTRUTURAS DE CONCRETO INTERNAS, COM COLHER DE PEDREIRO. ARGAMASSA TRAÇO 1:3 COM PREPARO EM BETONEIRA 400L. AF_10/2022 | E17: M2 | F17: 6.03 | G17: 14 | H17: 20 | I17: 28 | J17: =F17*G17 -> 84.42 | K17: =F17*H17 -> 120.6 | L17: =F17*I17 -> 168.84 | M17: chapisco
A18: 1. Banheiro com chuveiro | B18: 104958 | C18: SINAPI composição | D18: MASSA ÚNICA, EM ARGAMASSA TRAÇO 1:2:8 PREPARO MECÂNICO, APLICADA MANUALMENTE EM PAREDES INTERNAS DE AMBIENTES COM ÁREA MAIOR QUE 10M², E = 10MM, COM TALISCAS. AF_03/2024 | E18: M2 | F18: 31.79 | G18: 14 | H18: 20 | I18: 28 | J18: =F18*G18 -> 445.06 | K18: =F18*H18 -> 635.8 | L18: =F18*I18 -> 890.12 | M18: massa única
A19: 1. Banheiro com chuveiro | B19: 87265 | C19: SINAPI composição | D19: REVESTIMENTO CERÂMICO PARA PAREDES INTERNAS COM PLACAS TIPO ESMALTADA DE DIMENSÕES 20X20 CM APLICADAS NA ALTURA INTEIRA DAS PAREDES. AF_02/2023_PE | E19: M2 | F19: 59.3 | G19: 12.6 | H19: 18 | I19: 25.2 | J19: =F19*G19 -> 747.18 | K19: =F19*H19 -> 1067.4 | L19: =F19*I19 -> 1494.36 | M19: revestimento cerâmico
A20: 1. Banheiro com chuveiro | B20: 95241 | C20: SINAPI composição | D20: LASTRO DE CONCRETO MAGRO, APLICADO EM PISOS, LAJES SOBRE SOLO OU RADIERS, ESPESSURA DE 5 CM. AF_01/2024 | E20: M2 | F20: 48.41 | G20: 2.8 | H20: 4 | I20: 5.6 | J20: =F20*G20 -> 135.548 | K20: =F20*H20 -> 193.64 | L20: =F20*I20 -> 271.096 | M20: lastro de piso
A21: 1. Banheiro com chuveiro | B21: 98680 | C21: SINAPI composição | D21: PISO CIMENTADO, TRAÇO 1:5 (CIMENTO E AREIA), ACABAMENTO LISO, ESPESSURA 3,0 CM, PREPARO MECÂNICO DA ARGAMASSA. AF_02/2026 | E21: M2 | F21: 58.19 | G21: 2.8 | H21: 4 | I21: 5.6 | J21: =F21*G21 -> 162.932 | K21: =F21*H21 -> 232.76 | L21: =F21*I21 -> 325.864 | M21: regularização
A22: 1. Banheiro com chuveiro | B22: 87248 | C22: SINAPI composição | D22: REVESTIMENTO CERÂMICO PARA PISO COM PLACAS TIPO ESMALTADA DE DIMENSÕES 35X35 CM APLICADA EM AMBIENTES DE ÁREA MAIOR QUE 10 M2. AF_02/2023_PE | E22: M2 | F22: 50.14 | G22: 2.8 | H22: 4 | I22: 5.6 | J22: =F22*G22 -> 140.392 | K22: =F22*H22 -> 200.56 | L22: =F22*I22 -> 280.784 | M22: piso cerâmico
A23: 1. Banheiro com chuveiro | B23: 86931 | C23: SINAPI composição | D23: BACIA SANITÁRIA COM CAIXA ACOPLADA LOUÇA BRANCA, INCLUSO ENGATE FLEXÍVEL EM PLÁSTICO BRANCO, 1/2" X 40 CM - FORNECIMENTO E INSTALAÇÃO. AF_02/2026 | E23: UN | F23: 630.3 | G23: 1 | H23: 1 | I23: 1 | J23: =F23*G23 -> 630.3 | K23: =F23*H23 -> 630.3 | L23: =F23*I23 -> 630.3 | M23: bacia sanitária
A24: 1. Banheiro com chuveiro | B24: 86902 | C24: SINAPI composição | D24: LAVATÓRIO LOUÇA BRANCA COM COLUNA, *44 X 35* CM, PADRÃO POPULAR - FORNECIMENTO E INSTALAÇÃO. AF_02/2026 | E24: UN | F24: 368.02 | G24: 1 | H24: 1 | I24: 1 | J24: =F24*G24 -> 368.02 | K24: =F24*H24 -> 368.02 | L24: =F24*I24 -> 368.02 | M24: lavatório
A25: 1. Banheiro com chuveiro | B25: 100860 | C25: SINAPI composição | D25: CHUVEIRO ELÉTRICO COMUM CORPO PLÁSTICO, TIPO DUCHA - FORNECIMENTO E INSTALAÇÃO. AF_02/2026 | E25: UN | F25: 168.16 | G25: 1 | H25: 1 | I25: 1 | J25: =F25*G25 -> 168.16 | K25: =F25*H25 -> 168.16 | L25: =F25*I25 -> 168.16 | M25: chuveiro elétrico
A26: 1. Banheiro com chuveiro | B26: 89714 | C26: SINAPI composição | D26: TUBO PVC, SERIE NORMAL, ESGOTO PREDIAL, DN 100 MM, FORNECIDO E INSTALADO EM RAMAL DE DESCARGA OU RAMAL DE ESGOTO SANITÁRIO. AF_08/2022 | E26: M | F26: 43.26 | G26: 4.2 | H26: 6 | I26: 8.4 | J26: =F26*G26 -> 181.692 | K26: =F26*H26 -> 259.56 | L26: =F26*I26 -> 363.384 | M26: esgoto DN 100
A27: 1. Banheiro com chuveiro | B27: 92023 | C27: SINAPI composição | D27: INTERRUPTOR SIMPLES (1 MÓDULO) COM 1 TOMADA DE EMBUTIR 2P+T 10 A, INCLUINDO SUPORTE E PLACA - FORNECIMENTO E INSTALAÇÃO. AF_03/2023 | E27: UN | F27: 53.69 | G27: 2 | H27: 2 | I27: 2 | J27: =F27*G27 -> 107.38 | K27: =F27*H27 -> 107.38 | L27: =F27*I27 -> 107.38 | M27: pontos elétricos
... A33: 1. Banheiro com chuveiro | B33: 94440 | C33: SINAPI composição | D33: TELHAMENTO COM TELHA CERÂMICA DE ENCAIXE, TIPO FRANCESA, COM ATÉ 2 ÁGUAS, INCLUSO TRANSPORTE VERTICAL. AF_06/2026 | E33: M2 | F33: 42.42 | G33: 0 | H33: 0 | I33: 7 | J33: =F33*G33 -> 0 | K33: =F33*H33 -> 0 | L33: =F33*I33 -> 296.94 | M33: telha cerâmica
I34: Custo direto | J34: =SUM(J16:J33) -> 6439.88 | K34: =SUM(K16:K33) -> 7642.851 | L34: =SUM(L16:L33) -> 10255.276
I35: BDI | J35: =PARAMETROS!$B$6 -> 0.2034 | K35: =PARAMETROS!$C$6 -> 0.2212 | L35: =PARAMETROS!$D$6 -> 0.25
I36: Contingência | J36: =PARAMETROS!$B$8 -> 0.05 | K36: =PARAMETROS!$C$8 -> 0.1 | L36: =PARAMETROS!$D$8 -> 0.15
I37: Fator regional | J37: =PARAMETROS!$B$9 -> 1 | K37: =PARAMETROS!$C$9 -> 1 | L37: =PARAMETROS!$D$9 -> 1.1
I38: TOTAL ESTIMADO (R$) | J38: =J34*(1+J35)*(1+J36)*J37 -> 8137.2392 | K38: =K34*(1+K35)*(1+K36)*K37 -> 10266.795 | L38: =L34*(1+L35)*(1+L36)*L37 -> 16216.156
A40: Estimativa preliminar paramétrica, não vinculante, para planejamento orçamentário. Não substitui o orçamento detalhado do projeto. PROVISORIO - aguarda aprovacao

Sheet 05_MPBA_001.9.379764.2023
A1: 05 - Valetão aberto pela EMBASA em via pública (local não identificado)
A2: PROVISORIO - aguarda aprovacao
A4: Grupo-objeto | B4: MPBA_001.9.379764.2023
A5: Levantamento | B5: MP
A6: Origem | B6: MPBA
A7: Categoria | B7: drenagem
A8: Local | B8: não informado
A9: Fonte das quantidades | B9: demanda-tipo (local não identificado)
A10: Preços | B10: SINAPI/CAIXA ref. 08/2026, BA, não desonerado (código de cada item na coluna B)
A11: BDI aplicado | B11: vias e drenagem (Acórdão 2.622/2013, rodovias e ferrovias)
A12: Premissas | B12: Local do valetão não identificado; trecho de 50/100/200 m de rede com recomposição.
B13: A vala foi aberta pela EMBASA: parte do custo pode caber à concessionária.
B14: Microdrenagem em via existente: vala com largura DN + 0,6 m e profundidade DN + 1,0 m, PV a cada 40 m, 2 bocas de lobo a cada 40 m, recomposição de base (20 cm) e CBUQ (5 cm) na faixa da vala, bota-fora a 10 km.
A16: Macroetapa | B16: Código SINAPI | C16: Tipo | D16: Descrição | E16: Unid. | F16: Preço unit. (R$) | G16: Qtd. mínimo | H16: Qtd. provável | I16: Qtd. máximo | J16: Total mínimo (R$) | K16: Total provável (R$) | L16: Total máximo (R$) | M16: Memória de cálculo
A17: 1. Serviços preliminares | B17: 103689 | C17: SINAPI composição | D17: FORNECIMENTO E INSTALAÇÃO DE PLACA DE OBRA COM CHAPA GALVANIZADA E ESTRUTURA DE MADEIRA. AF_03/2022_PS | E17: M2 | F17: 454.97 | G17: 6 | H17: 6 | I17: 6 | J17: =F17*G17 -> 2729.82 | K17: =F17*H17 -> 2729.82 | L17: =F17*I17 -> 2729.82 | M17: placa de obra 3 m x 2 m
A18: 2. Drenagem | B18: 90082 | C18: SINAPI composição | D18: ESCAVAÇÃO MECANIZADA DE VALA COM PROF. ATÉ 1,5 M (MÉDIA MONTANTE E JUSANTE/UMA COMPOSIÇÃO POR TRECHO), ESCAVADEIRA (0,8 M3), LARG. DE 1,5 M A 2,5 M, EM SOLO DE 1A CATEGORIA, EM LOCAIS COM ALTO NÍVEL DE INTERFERÊNCIA. AF_09/2024 | E18: M3 | F18: 10.58 | G18: 96 | H18: 0 | I18: 0 | J18: =F18*G18 -> 1015.68 | K18: =F18*H18 -> 0 | L18: =F18*I18 -> 0 | M18: vala 1.20 m x 1.60 m x L 50 m
A19: 2. Drenagem | B19: 92212 | C19: SINAPI composição | D19: TUBO DE CONCRETO PARA REDES COLETORAS DE ÁGUAS PLUVIAIS, DIÂMETRO DE 600 MM, JUNTA RÍGIDA, INSTALADO EM LOCAL COM BAIXO NÍVEL DE INTERFERÊNCIAS - FORNECIMENTO E ASSENTAMENTO. AF_03/2024 | E19: M | F19: 351.67 | G19: 50 | H19: 100 | I19: 0 | J19: =F19*G19 -> 17583.5 | K19: =F19*H19 -> 35167 | L19: =F19*I19 -> 0 | M19: rede DN 600 mm ao longo de L
A20: 2. Drenagem | B20: 93369 | C20: SINAPI composição | D20: REATERRO MECANIZADO DE VALA COM ESCAVADEIRA HIDRÁULICA (CAPACIDADE DA CAÇAMBA: 0,8 M³/POTÊNCIA: 111 HP), LARGURA 1,5 A 2,5 M, PROFUNDIDADE 1,5 A 3,0 M, COM SOLO (SEM SUBSTITUIÇÃO) DE 1ª CATEGORIA, COM COMPACTADOR DE SOLOS DE PERCUSSÃO. AF_08/2023 | E20: M3 | F20: 20.26 | G20: 76.76 | H20: 153.52 | I20: 376.77 | J20: =F20*G20 -> 1555.1576 | K20: =F20*H20 -> 3110.3152 | L20: =F20*I20 -> 7633.3602 | M20: volume da vala - volume externo do tubo
A21: 2. Drenagem | B21: 99285 | C21: SINAPI composição | D21: BASE PARA POÇO DE VISITA CIRCULAR PARA DRENAGEM, EM CONCRETO PRÉ-MOLDADO, DIÂMETRO INTERNO = 1,0 M, PROFUNDIDADE = 1,35 M, EXCLUINDO TAMPÃO. AF_05/2018 | E21: UN | F21: 1613.82 | G21: 3 | H21: 4 | I21: 0 | J21: =F21*G21 -> 4841.46 | K21: =F21*H21 -> 6455.28 | L21: =F21*I21 -> 0 | M21: PV a cada 40 m + 1
A22: 2. Drenagem | B22: 99288 | C22: SINAPI composição | D22: ACRÉSCIMO PARA POÇO DE VISITA CIRCULAR PARA DRENAGEM, EM CONCRETO PRÉ-MOLDADO, DIÂMETRO INTERNO = 1 M. AF_12/2020 | E22: M | F22: 634.89 | G22: 1.5 | H22: 2 | I22: 0 | J22: =F22*G22 -> 952.335 | K22: =F22*H22 -> 1269.78 | L22: =F22*I22 -> 0 | M22: acréscimo médio de 0,5 m de profundidade por PV
A23: 2. Drenagem | B23: 97956 | C23: SINAPI composição | D23: CAIXA PARA BOCA DE LOBO SIMPLES RETANGULAR, EM ALVENARIA COM BLOCOS DE CONCRETO, DIMENSÕES INTERNAS: 0,6X1X1,2 M. AF_12/2020 | E23: UN | F23: 1812.94 | G23: 4 | H23: 6 | I23: 10 | J23: =F23*G23 -> 7251.76 | K23: =F23*H23 -> 10877.64 | L23: =F23*I23 -> 18129.4 | M23: boca de lobo simples, 2 a cada 40 m
A24: 2. Drenagem | B24: 92210 | C24: SINAPI composição | D24: TUBO DE CONCRETO PARA REDES COLETORAS DE ÁGUAS PLUVIAIS, DIÂMETRO DE 400 MM, JUNTA RÍGIDA, INSTALADO EM LOCAL COM BAIXO NÍVEL DE INTERFERÊNCIAS - FORNECIMENTO E ASSENTAMENTO. AF_03/2024 | E24: M | F24: 188.74 | G24: 16 | H24: 24 | I24: 40 | J24: =F24*G24 -> 3019.84 | K24: =F24*H24 -> 4529.76 | L24: =F24*I24 -> 7549.6 | M24: ligação BL-PV em DN 400 mm, 4 m por boca de lobo
A25: 2. Drenagem | B25: 100982 | C25: SINAPI composição | D25: CARGA, MANOBRA E DESCARGA DE ENTULHO EM CAMINHÃO BASCULANTE 10 M³ - CARGA COM ESCAVADEIRA HIDRÁULICA (CAÇAMBA DE 0,80 M³ / 111 HP) E DESCARGA LIVRE (UNIDADE: M3). AF_02/2026 | E25: M3 | F25: 9.88 | G25: 19.24 | H25: 38.48 | I25: 127.23 | J25: =F25*G25 -> 190.0912 | K25: =F25*H25 -> 380.1824 | L25: =F25*I25 -> 1257.0324 | M25: carga do solo excedente (volume do tubo)
A26: 2. Drenagem | B26: 95875 | C26: SINAPI composição | D26: TRANSPORTE COM CAMINHÃO BASCULANTE DE 10 M³, EM VIA URBANA PAVIMENTADA, DMT ATÉ 30 KM (UNIDADE: M3XKM). AF_02/2026 | E26: M3XKM | F26: 2.83 | G26: 192.42 | H26: 384.85 | I26: 1272.35 | J26: =F26*G26 -> 544.5486 | K26: =F26*H26 -> 1089.1255 | L26: =F26*I26 -> 3600.7505 | M26: transporte do excedente, DMT 10 km
A27: 3. Recomposição do pavimento | B27: 101849 | C27: SINAPI composição | D27: RECOMPOSIÇÃO DE BASE E OU SUB-BASE PARA FECHAMENTO DE VALAS DE BRITA GRADUADA SIMPLES - INCLUSO RETIRADA E COLOCAÇÃO DO MATERIAL. AF_12/2020 | E27: M3 | F27: 232.27 | G27: 14 | H27: 28 | I27: 0 | J27: =F27*G27 -> 3251.78 | K27: =F27*H27 -> 6503.56 | L27: =F27*I27 -> 0 | M27: base de brita graduada 20 cm na faixa da vala (1.40 m)
A28: 3. Recomposição do pavimento | B28: 102098 | C28: SINAPI composição | D28: RECOMPOSIÇÃO DE REVESTIMENTO EM CONCRETO ASFÁLTICO (AQUISIÇÃO EM USINA), PARA O FECHAMENTO DE VALAS - INCLUSO DEMOLIÇÃO DO PAVIMENTO. AF_12/2020 | E28: M3 | F28: 2136.03 | G28: 3.5 | H28: 7 | I28: 16 | J28: =F28*G28 -> 7476.105 | K28: =F28*H28 -> 14952.21 | L28: =F28*I28 -> 34176.48 | M28: revestimento em CBUQ 5 cm na faixa da vala (inclui demolição)
... A34: 3. Recomposição do pavimento | B34: 101849 | C34: SINAPI composição | D34: RECOMPOSIÇÃO DE BASE E OU SUB-BASE PARA FECHAMENTO DE VALAS DE BRITA GRADUADA SIMPLES - INCLUSO RETIRADA E COLOCAÇÃO DO MATERIAL. AF_12/2020 | E34: M3 | F34: 232.27 | G34: 0 | H34: 0 | I34: 64 | J34: =F34*G34 -> 0 | K34: =F34*H34 -> 0 | L34: =F34*I34 -> 14865.28 | M34: base de brita graduada 20 cm na faixa da vala (1.60 m)
I35: Custo direto | J35: =SUM(J17:J34) -> 50412.077 | K35: =SUM(K17:K34) -> 89096.033 | L35: =SUM(L17:L34) -> 223450.84
I36: BDI | J36: =PARAMETROS!$B$7 -> 0.196 | K36: =PARAMETROS!$C$7 -> 0.2097 | L36: =PARAMETROS!$D$7 -> 0.2423
I37: Contingência | J37: =PARAMETROS!$B$8 -> 0.05 | K37: =PARAMETROS!$C$8 -> 0.1 | L37: =PARAMETROS!$D$8 -> 0.15
I38: Fator regional | J38: =PARAMETROS!$B$9 -> 1 | K38: =PARAMETROS!$C$9 -> 1 | L38: =PARAMETROS!$D$9 -> 1.1
I39: TOTAL ESTIMADO (R$) | J39: =J35*(1+J36)*(1+J37)*J38 -> 63307.487 | K39: =K35*(1+K36)*(1+K37)*K38 -> 118557.42 | L39: =L35*(1+L36)*(1+L37)*L38 -> 351155.12
A41: Estimativa preliminar paramétrica, não vinculante, para planejamento orçamentário. Não substitui o orçamento detalhado do projeto. PROVISORIO - aguarda aprovacao

Sheet 06_MPBA_001.9.52800.2024
A1: 06 - Quadra poliesportiva do distrito de Banco do Pedro
A2: PROVISORIO - aguarda aprovacao
A4: Grupo-objeto | B4: MPBA_001.9.52800.2024
A5: Levantamento | B5: MP
A6: Origem | B6: MPBA
A7: Categoria | B7: quadra/esporte
A8: Local | B8: Distrito de Banco do Pedro
A9: Fonte das quantidades | B9: documento (1 quadra) + demanda-tipo
A10: Preços | B10: SINAPI/CAIXA ref. 08/2026, BA, não desonerado (código de cada item na coluna B)
A11: BDI aplicado | B11: edificações (Acórdão 2.622/2013, construção de edifícios)
A12: Premissas | B12: Quadra poliesportiva coberta-tipo: piso 32 m x 20 m em concreto armado, cobertura metálica de 748 m², alambrado de 104 m.
B13: Estrutura de aço 18/25/32 kg/m²; vestiário de 0/40/60 m².
B14: Iluminação esportiva representada por refletores do SINAPI; o projeto luminotécnico pode elevar o custo.
A16: Macroetapa | B16: Código SINAPI | C16: Tipo | D16: Descrição | E16: Unid. | F16: Preço unit. (R$) | G16: Qtd. mínimo | H16: Qtd. provável | I16: Qtd. máximo | J16: Total mínimo (R$) | K16: Total provável (R$) | L16: Total máximo (R$) | M16: Memória de cálculo
A17: 1. Serviços preliminares | B17: 103689 | C17: SINAPI composição | D17: FORNECIMENTO E INSTALAÇÃO DE PLACA DE OBRA COM CHAPA GALVANIZADA E ESTRUTURA DE MADEIRA. AF_03/2022_PS | E17: M2 | F17: 454.97 | G17: 6 | H17: 6 | I17: 6 | J17: =F17*G17 -> 2729.82 | K17: =F17*H17 -> 2729.82 | L17: =F17*I17 -> 2729.82 | M17: placa de obra
A18: 1. Serviços preliminares | B18: 98525 | C18: SINAPI composição | D18: LIMPEZA MECANIZADA DE CAMADA VEGETAL, VEGETAÇÃO E PEQUENAS ÁRVORES (DIÂMETRO DE TRONCO MENOR QUE 0,20 M), COM TRATOR DE ESTEIRAS. AF_03/2024 | E18: M2 | F18: 0.76 | G18: 900 | H18: 900 | I18: 900 | J18: =F18*G18 -> 684 | K18: =F18*H18 -> 684 | L18: =F18*I18 -> 684 | M18: limpeza do terreno
A19: 2. Fundações e pilares | B19: 93358 | C19: SINAPI composição | D19: ESCAVAÇÃO MANUAL DE VALA. AF_09/2024 | E19: M3 | F19: 103.4 | G19: 30 | H19: 30 | I19: 30 | J19: =F19*G19 -> 3102 | K19: =F19*H19 -> 3102 | L19: =F19*I19 -> 3102 | M19: escavação de blocos
A20: 2. Fundações e pilares | B20: 103672 | C20: SINAPI composição | D20: CONCRETAGEM DE PILARES, FCK = 25 MPA, COM USO DE BOMBA - LANÇAMENTO, ADENSAMENTO E ACABAMENTO. AF_02/2022_PS | E20: M3 | F20: 828.32 | G20: 15 | H20: 15 | I20: 15 | J20: =F20*G20 -> 12424.8 | K20: =F20*H20 -> 12424.8 | L20: =F20*I20 -> 12424.8 | M20: concreto de blocos e pilares
A21: 2. Fundações e pilares | B21: 92762 | C21: SINAPI composição | D21: ARMAÇÃO DE PILAR OU VIGA DE ESTRUTURA CONVENCIONAL DE CONCRETO ARMADO UTILIZANDO AÇO CA-50 DE 10,0 MM - MONTAGEM. AF_06/2022 | E21: KG | F21: 10.41 | G21: 1500 | H21: 1500 | I21: 1500 | J21: =F21*G21 -> 15615 | K21: =F21*H21 -> 15615 | L21: =F21*I21 -> 15615 | M21: armação
A22: 2. Fundações e pilares | B22: 92421 | C22: SINAPI composição | D22: MONTAGEM E DESMONTAGEM DE FÔRMA DE PILARES RETANGULARES E ESTRUTURAS SIMILARES, PÉ-DIREITO DUPLO, EM CHAPA DE MADEIRA COMPENSADA RESINADA, 4 UTILIZAÇÕES. AF_09/2020 | E22: M2 | F22: 122.64 | G22: 120 | H22: 120 | I22: 120 | J22: =F22*G22 -> 14716.8 | K22: =F22*H22 -> 14716.8 | L22: =F22*I22 -> 14716.8 | M22: fôrmas
A23: 3. Piso esportivo | B23: 100576 | C23: SINAPI composição | D23: REGULARIZAÇÃO E COMPACTAÇÃO DE SUBLEITO DE SOLO PREDOMINANTEMENTE ARGILOSO, PARA OBRAS DE CONSTRUÇÃO DE PAVIMENTOS. AF_09/2024 | E23: M2 | F23: 3.35 | G23: 640 | H23: 640 | I23: 640 | J23: =F23*G23 -> 2144 | K23: =F23*H23 -> 2144 | L23: =F23*I23 -> 2144 | M23: regularização (área 32 m x 20 m)
A24: 3. Piso esportivo | B24: 96396 | C24: SINAPI composição | D24: CONSTRUÇÃO DE BASE E SUB-BASE PARA PAVIMENTAÇÃO DE BRITA GRADUADA SIMPLES, COM ESPESSURA DE 15 CM - EXCLUSIVE CARGA E TRANSPORTE. AF_09/2024 | E24: M3 | F24: 216.4 | G24: 64 | H24: 64 | I24: 64 | J24: =F24*G24 -> 13849.6 | K24: =F24*H24 -> 13849.6 | L24: =F24*I24 -> 13849.6 | M24: base de brita graduada 10 cm
A25: 3. Piso esportivo | B25: 94995 | C25: SINAPI composição | D25: EXECUÇÃO DE PASSEIO (CALÇADA) OU PISO DE CONCRETO COM CONCRETO MOLDADO IN LOCO, USINADO, ACABAMENTO CONVENCIONAL, ESPESSURA 8 CM, ARMADO. AF_08/2022 | E25: M2 | F25: 103.21 | G25: 640 | H25: 640 | I25: 640 | J25: =F25*G25 -> 66054.4 | K25: =F25*H25 -> 66054.4 | L25: =F25*I25 -> 66054.4 | M25: piso de concreto armado 8 cm
A26: 3. Piso esportivo | B26: 102504 | C26: SINAPI composição | D26: PINTURA DE DEMARCAÇÃO DE QUADRA POLIESPORTIVA COM TINTA ACRÍLICA, E = 5 CM, APLICAÇÃO MANUAL. AF_05/2021 | E26: M | F26: 12.45 | G26: 250 | H26: 250 | I26: 250 | J26: =F26*G26 -> 3112.5 | K26: =F26*H26 -> 3112.5 | L26: =F26*I26 -> 3112.5 | M26: demarcação das quadras
A27: 4. Cobertura | B27: 104314 | C27: SINAPI composição | D27: TRAMA DE AÇO COMPOSTA POR TERÇAS PARA TELHADOS DE ATÉ 2 ÁGUAS PARA TELHA ONDULADA DE FIBROCIMENTO, METÁLICA, PLÁSTICA OU TERMOACÚSTICA, INCLUSO TRANSPORTE VERTICAL (EM KG). EXCLUSIVE PINTURA. AF_10/2025_PS | E27: KG | F27: 13.77 | G27: 13464 | H27: 0 | I27: 0 | J27: =F27*G27 -> 185399.28 | K27: =F27*H27 -> 0 | L27: =F27*I27 -> 0 | M27: estrutura de aço da cobertura, 18 kg/m² em 748 m²
A28: 4. Cobertura | B28: 94216 | C28: SINAPI composição | D28: TELHAMENTO COM TELHA METÁLICA TERMOACÚSTICA E = 30 MM, COM ATÉ 2 ÁGUAS, INCLUSO IÇAMENTO. AF_06/2026 | E28: M2 | F28: 192.73 | G28: 748 | H28: 748 | I28: 748 | J28: =F28*G28 -> 144162.04 | K28: =F28*H28 -> 144162.04 | L28: =F28*I28 -> 144162.04 | M28: telha metálica termoacústica
... A67: 4. Cobertura | B67: 104314 | C67: SINAPI composição | D67: TRAMA DE AÇO COMPOSTA POR TERÇAS PARA TELHADOS DE ATÉ 2 ÁGUAS PARA TELHA ONDULADA DE FIBROCIMENTO, METÁLICA, PLÁSTICA OU TERMOACÚSTICA, INCLUSO TRANSPORTE VERTICAL (EM KG). EXCLUSIVE PINTURA. AF_10/2025_PS | E67: KG | F67: 13.77 | G67: 0 | H67: 0 | I67: 23936 | J67: =F67*G67 -> 0 | K67: =F67*H67 -> 0 | L67: =F67*I67 -> 329598.72 | M67: estrutura de aço da cobertura, 32 kg/m² em 748 m²
I68: Custo direto | J68: =SUM(J17:J67) -> 505094.91 | K68: =SUM(K17:K67) -> 636945.47 | L68: =SUM(L17:L67) -> 737854.44
I69: BDI | J69: =PARAMETROS!$B$6 -> 0.2034 | K69: =PARAMETROS!$C$6 -> 0.2212 | L69: =PARAMETROS!$D$6 -> 0.25
I70: Contingência | J70: =PARAMETROS!$B$8 -> 0.05 | K70: =PARAMETROS!$C$8 -> 0.1 | L70: =PARAMETROS!$D$8 -> 0.15
I71: Fator regional | J71: =PARAMETROS!$B$9 -> 1 | K71: =PARAMETROS!$C$9 -> 1 | L71: =PARAMETROS!$D$9 -> 1.1
I72: TOTAL ESTIMADO (R$) | J72: =J68*(1+J69)*(1+J70)*J71 -> 638222.78 | K72: =K68*(1+K69)*(1+K70)*K71 -> 855621.59 | L72: =L68*(1+L69)*(1+L70)*L71 -> 1166732.3
A74: Estimativa preliminar paramétrica, não vinculante, para planejamento orçamentário. Não substitui o orçamento detalhado do projeto. PROVISORIO - aguarda aprovacao

Sheet 07_MPBA_003.9.153337.2023
A1: 07 - Reforma do Instituto Municipal de Ensino Eusínio Lavigne – IME (Av. Canavieiras, Centro)
A2: PROVISORIO - aguarda aprovacao
A4: Grupo-objeto | B4: MPBA_003.9.153337.2023
A5: Levantamento | B5: MP
A6: Origem | B6: MPBA
A7: Categoria | B7: escola/creche
A8: Local | B8: Instituto Municipal de Ensino Eusínio Lavigne (IME), Av. Canavieiras, s/n, Centro
A9: Fonte das quantidades | B9: demanda-tipo (área a confirmar)
A10: Preços | B10: SINAPI/CAIXA ref. 08/2026, BA, não desonerado (código de cada item na coluna B)
A11: BDI aplicado | B11: edificações (Acórdão 2.622/2013, construção de edifícios)
A12: Premissas | B12: Prédio escolar de 1939 com dois pavimentos; área de 1.500/2.000/2.500 m² (premissa; confirmar).
B13: Inclui requalificação de cobertura pedida pela 6ª PJ. Exigências de preservação histórica podem elevar o custo.
B14: Reforma-tipo por m²: fração refeita de cobertura/forro/piso/reboco/esquadrias/instalações = 20/20/10/10/10/20% (mín), 50/50/30/30/30/50% (prov) e 100/100/60/60/60/100% (máx); pintura integral; extintores, emergência e sinalização de rota de fuga.
A16: Macroetapa | B16: Código SINAPI | C16: Tipo | D16: Descrição | E16: Unid. | F16: Preço unit. (R$) | G16: Qtd. mínimo | H16: Qtd. provável | I16: Qtd. máximo | J16: Total mínimo (R$) | K16: Total provável (R$) | L16: Total máximo (R$) | M16: Memória de cálculo
A17: 1. Serviços preliminares | B17: 103689 | C17: SINAPI composição | D17: FORNECIMENTO E INSTALAÇÃO DE PLACA DE OBRA COM CHAPA GALVANIZADA E ESTRUTURA DE MADEIRA. AF_03/2022_PS | E17: M2 | F17: 454.97 | G17: 6 | H17: 6 | I17: 6 | J17: =F17*G17 -> 2729.82 | K17: =F17*H17 -> 2729.82 | L17: =F17*I17 -> 2729.82 | M17: placa de obra
A18: 2. Demolições e retiradas | B18: 97647 | C18: SINAPI composição | D18: REMOÇÃO DE TELHAS DE FIBROCIMENTO METÁLICA E CERÂMICA, DE FORMA MANUAL, SEM REAPROVEITAMENTO. AF_09/2023 | E18: M2 | F18: 4.43 | G18: 375 | H18: 1250 | I18: 3125 | J18: =F18*G18 -> 1661.25 | K18: =F18*H18 -> 5537.5 | L18: =F18*I18 -> 13843.75 | M18: remoção de telhas
A19: 2. Demolições e retiradas | B19: 97650 | C19: SINAPI composição | D19: REMOÇÃO DE TRAMA DE MADEIRA PARA COBERTURA, DE FORMA MANUAL, SEM REAPROVEITAMENTO. AF_09/2023 | E19: M2 | F19: 9.56 | G19: 187.5 | H19: 625 | I19: 1562.5 | J19: =F19*G19 -> 1792.5 | K19: =F19*H19 -> 5975 | L19: =F19*I19 -> 14937.5 | M19: remoção de trama de madeira (metade da área refeita)
A20: 2. Demolições e retiradas | B20: 97640 | C20: SINAPI composição | D20: REMOÇÃO DE FORROS DE DRYWALL, PVC E FIBROMINERAL, DE FORMA MANUAL, SEM REAPROVEITAMENTO. AF_09/2023 | E20: M2 | F20: 2.58 | G20: 300 | H20: 1000 | I20: 2500 | J20: =F20*G20 -> 774 | K20: =F20*H20 -> 2580 | L20: =F20*I20 -> 6450 | M20: remoção de forro
A21: 2. Demolições e retiradas | B21: 97634 | C21: SINAPI composição | D21: DEMOLIÇÃO DE REVESTIMENTO CERÂMICO, DE FORMA MECANIZADA COM MARTELETE, SEM REAPROVEITAMENTO. AF_09/2023 | E21: M2 | F21: 10.04 | G21: 150 | H21: 600 | I21: 1500 | J21: =F21*G21 -> 1506 | K21: =F21*H21 -> 6024 | L21: =F21*I21 -> 15060 | M21: demolição de piso cerâmico
A22: 2. Demolições e retiradas | B22: 97633 | C22: SINAPI composição | D22: DEMOLIÇÃO DE REVESTIMENTO CERÂMICO, DE FORMA MANUAL, SEM REAPROVEITAMENTO. AF_09/2023 | E22: M2 | F22: 28.42 | G22: 45 | H22: 180 | I22: 450 | J22: =F22*G22 -> 1278.9 | K22: =F22*H22 -> 5115.6 | L22: =F22*I22 -> 12789 | M22: demolição de revestimento de parede
A23: 2. Demolições e retiradas | B23: 97645 | C23: SINAPI composição | D23: REMOÇÃO DE JANELAS, DE FORMA MANUAL, SEM REAPROVEITAMENTO. AF_09/2023 | E23: M2 | F23: 30.78 | G23: 22.5 | H23: 90 | I23: 225 | J23: =F23*G23 -> 692.55 | K23: =F23*H23 -> 2770.2 | L23: =F23*I23 -> 6925.5 | M23: remoção de janelas
A24: 3. Cobertura e forro | B24: 92539 | C24: SINAPI composição | D24: TRAMA DE MADEIRA COMPOSTA POR RIPAS, CAIBROS E TERÇAS PARA TELHADOS DE ATÉ 2 ÁGUAS PARA TELHA CERÂMICA OU DE CONCRETO, INCLUSO TRANSPORTE VERTICAL. AF_10/2025 | E24: M2 | F24: 101.54 | G24: 187.5 | H24: 625 | I24: 1562.5 | J24: =F24*G24 -> 19038.75 | K24: =F24*H24 -> 63462.5 | L24: =F24*I24 -> 158656.25 | M24: trama de madeira nova
A25: 3. Cobertura e forro | B25: 94440 | C25: SINAPI composição | D25: TELHAMENTO COM TELHA CERÂMICA DE ENCAIXE, TIPO FRANCESA, COM ATÉ 2 ÁGUAS, INCLUSO TRANSPORTE VERTICAL. AF_06/2026 | E25: M2 | F25: 42.42 | G25: 375 | H25: 1250 | I25: 3125 | J25: =F25*G25 -> 15907.5 | K25: =F25*H25 -> 53025 | L25: =F25*I25 -> 132562.5 | M25: telha cerâmica nova
A26: 3. Cobertura e forro | B26: 96116 | C26: SINAPI composição | D26: FORRO EM RÉGUAS DE PVC, FRISADO, PARA AMBIENTES COMERCIAIS, INCLUSIVE ESTRUTURA BIDIRECIONAL DE FIXAÇÃO. AF_08/2023_PS | E26: M2 | F26: 73.2 | G26: 300 | H26: 1000 | I26: 2500 | J26: =F26*G26 -> 21960 | K26: =F26*H26 -> 73200 | L26: =F26*I26 -> 183000 | M26: forro de PVC novo
